<?xml version="1.0" ?>
<sdf version='1.5'>
  <model name='iris_mid360'>
    <include>
      <uri>model://iris</uri>
    </include>
    <include>
      <uri>model://mid360</uri>
      <pose>0 0 0.06 0 0 0</pose>
    </include>
    <!-- <include>
      <uri>model://rgb_cam</uri>
      <pose>0 0 -0.03 0 1.5707963 0</pose>
    </include> -->
    <joint name="mid360_joint" type="revolute">
      <child>mid360::link_0</child>
      <parent>iris::base_link</parent>
    </joint>
    <!-- <joint name="cam_joint" type="revolute">
      <child>rgb_cam::link_0</child>
      <parent>iris::base_link</parent>
    </joint> -->
  </model>
</sdf>
